{"timestamp":"2024-11-30 18:00:58,643", "level":"ERROR", "error_id":"ERR-20241130180058-4", "component":"telegram_bot", "message":"This Application is not running!", "details":{"error_type": "RuntimeError", "error_message": "This Application is not running!", "stack_trace": "Traceback (most recent call last):\n  File \"/home/runner/TherapyyyBot/main.py\", line 96, in main\n    await cleanup_bot.stop()\n  File \"/home/runner/TherapyyyBot/bot_handlers.py\", line 423, in stop\n    await self.application.stop()\n  File \"/home/runner/TherapyyyBot/.pythonlibs/lib/python3.11/site-packages/telegram/ext/_application.py\", line 661, in stop\n    raise RuntimeError(\"This Application is not running!\")\nRuntimeError: This Application is not running!\n", "context": {"timestamp": "2024-11-30T18:00:58.642954", "update": null, "user_id": null, "additional_context": {"stage": "cleanup"}}}}
{"timestamp":"2024-11-30 18:00:58,644", "level":"ERROR", "error_id":"ERR-20241130180058-4", "component":"telegram_bot", "message":"This Application is not running!", "details":{"error_type": "RuntimeError", "error_message": "This Application is not running!", "stack_trace": "Traceback (most recent call last):\n  File \"/home/runner/TherapyyyBot/main.py\", line 104, in main\n    await cleanup_bot.stop()\n  File \"/home/runner/TherapyyyBot/bot_handlers.py\", line 423, in stop\n    await self.application.stop()\n  File \"/home/runner/TherapyyyBot/.pythonlibs/lib/python3.11/site-packages/telegram/ext/_application.py\", line 661, in stop\n    raise RuntimeError(\"This Application is not running!\")\nRuntimeError: This Application is not running!\n", "context": {"timestamp": "2024-11-30T18:00:58.644271", "update": null, "user_id": null, "additional_context": {"stage": "cleanup_shutdown"}}}}
{"timestamp":"2024-11-30 18:01:22,840", "level":"ERROR", "error_id":"ERR-20241130180122-1", "component":"telegram_bot", "message":"This Application is not running!", "details":{"error_type": "RuntimeError", "error_message": "This Application is not running!", "stack_trace": "Traceback (most recent call last):\n  File \"/home/runner/TherapyyyBot/main.py\", line 96, in main\n    await cleanup_bot.stop()\n  File \"/home/runner/TherapyyyBot/bot_handlers.py\", line 423, in stop\n    await self.application.stop()\n  File \"/home/runner/TherapyyyBot/.pythonlibs/lib/python3.11/site-packages/telegram/ext/_application.py\", line 661, in stop\n    raise RuntimeError(\"This Application is not running!\")\nRuntimeError: This Application is not running!\n", "context": {"timestamp": "2024-11-30T18:01:22.840002", "update": null, "user_id": null, "additional_context": {"stage": "cleanup"}}}}
{"timestamp":"2024-11-30 18:01:22,841", "level":"ERROR", "error_id":"ERR-20241130180122-1", "component":"telegram_bot", "message":"This Application is not running!", "details":{"error_type": "RuntimeError", "error_message": "This Application is not running!", "stack_trace": "Traceback (most recent call last):\n  File \"/home/runner/TherapyyyBot/main.py\", line 104, in main\n    await cleanup_bot.stop()\n  File \"/home/runner/TherapyyyBot/bot_handlers.py\", line 423, in stop\n    await self.application.stop()\n  File \"/home/runner/TherapyyyBot/.pythonlibs/lib/python3.11/site-packages/telegram/ext/_application.py\", line 661, in stop\n    raise RuntimeError(\"This Application is not running!\")\nRuntimeError: This Application is not running!\n", "context": {"timestamp": "2024-11-30T18:01:22.841303", "update": null, "user_id": null, "additional_context": {"stage": "cleanup_shutdown"}}}}
